Workbook

Sheet Summary
A1: This project involved answering questions from a large movie dataset to find changes in revenue over time, trends with certain genres, ratings, and scores. Gross revenue generally increased from 1980 to 2019 with some minor year to year fluctuations, and before the sharp decline in 2020 due to the COVID-19 pandemic that affected the entire movie industry. The data showed that older movie revenues require a much larger inflation adjustment. It narrows more with recent releases. Movies with higher scores do not appear to have a strong relationship with gross relative to budget. The ratio remains relatively flat across the board with a few outliers. R-Rated films generated approximately 2.55 times their budget in gross revenue, but not have the highest gross relative to budget. Smaller sample sizes with TV-MA and Not Rated movies should be interpreted with caution despite the higher ratios. Among the genres, action films had the highest gross relative budget at 2.93, followed by Comedy at 2.84, and Drama at 2.83.

Sheet PivotTable
A3: year | B3: Sum of gross
A4: 1980 | B4: 2483666964
A5: 1981 | B5: 2520064889
A6: 1982 | B6: 3187580517
A7: 1983 | B7: 2750004626
A8: 1984 | B8: 3533092196
A9: 1985 | B9: 3691509283
A10: 1986 | B10: 3647511836
A11: 1987 | B11: 4033434255
A12: 1988 | B12: 4840385631
A13: 1989 | B13: 6087250779
A14: 1990 | B14: 6804235860
A15: 1991 | B15: 6254770668
... A44: 2020 | B44: 2848298792
A45: (blank)
A46: Grand Total | B46: 587105546272

Sheet Revenue Analysis
A3: year | B3: Sum of gross | C3: Sum of budget | F3: year | G3: Gross relative to budget
A4: 1980 | B4: 2483666964 | C4: 568850000 | F4: =A4 -> 1980 | G4: =B4 / C4 -> 4.3661193
A5: 1981 | B5: 2520064889 | C5: 709450000 | F5: =A5 -> 1981 | G5: =B5 / C5 -> 3.5521388
A6: 1982 | B6: 3187580517 | C6: 836670000 | F6: =A6 -> 1982 | G6: =B6 / C6 -> 3.809842
A7: 1983 | B7: 2750004626 | C7: 893975562 | F7: =A7 -> 1983 | G7: =B7 / C7 -> 3.0761519
A8: 1984 | B8: 3533092196 | C8: 1116326000 | F8: =A8 -> 1984 | G8: =B8 / C8 -> 3.1649287
A9: 1985 | B9: 3691509283 | C9: 1220510000 | F9: =A9 -> 1985 | G9: =B9 / C9 -> 3.0245629
A10: 1986 | B10: 3647511836 | C10: 1264787376 | F10: =A10 -> 1986 | G10: =B10 / C10 -> 2.8838933
A11: 1987 | B11: 4033434255 | C11: 1382542678 | F11: =A11 -> 1987 | G11: =B11 / C11 -> 2.9174031
A12: 1988 | B12: 4840385631 | C12: 1730540000 | F12: =A12 -> 1988 | G12: =B12 / C12 -> 2.7970377
A13: 1989 | B13: 6087250779 | C13: 1784762578 | F13: =A13 -> 1989 | G13: =B13 / C13 -> 3.4106782
A14: 1990 | B14: 6804235860 | C14: 2072503000 | F14: =A14 -> 1990 | G14: =B14 / C14 -> 3.2831006
A15: 1991 | B15: 6254770668 | C15: 2268248000 | F15: =A15 -> 1991 | G15: =B15 / C15 -> 2.7575339
... A44: 2020 | B44: 2848298792 | C44: 862965750 | F44: =A44 -> 2020 | G44: =B44 / C44 -> 3.3005931
A45: (blank)
A46: Grand Total | B46: 587105546272 | C46: 195637549431

Sheet CPI
A1: Year | B1: Annual Average CPI
A2: 1913 | B2: 9.9
A3: 1914 | B3: 10
A4: 1915 | B4: 10.1
A5: 1916 | B5: 10.9
A6: 1917 | B6: 12.8
A7: 1918 | B7: 15
A8: 1919 | B8: 17.3
A9: 1920 | B9: 20
A10: 1921 | B10: 17.9
A11: 1922 | B11: 16.8
A12: 1923 | B12: 17.1
A13: 1924 | B13: 17.1
... A114: 2025 | B114: 321.9
A115: 2026* | B115: 334.4

Sheet Movies
A1: name | B1: rating | C1: genre | D1: year | E1: released | F1: score | G1: votes | H1: director | I1: writer | J1: star | K1: country | L1: budget | M1: gross | N1: company | O1: runtime | P1: cpi of release year | Q1: gross revenue in 2023 dollars
A2: The Shining | B2: R | C2: Drama | D2: 1980 | E2: June 13, 1980 (United States) | F2: 8.4 | G2: 927000 | H2: Stanley Kubrick | I2: Stephen King | J2: Jack Nicholson | K2: United Kingdom | L2: 19000000 | M2: 46998772 | N2: Warner Bros. | O2: 146 | P2: {=_xlfn.XLOOKUP(D2, CPI!$A:A, CPI!$B:B)} -> 82.4 | Q2: =IF(M2="","",PRODUCT(M2,CPI!$B$112/P2)) -> 1.7379279e+08
A3: The Blue Lagoon | B3: R | C3: Adventure | D3: 1980 | E3: July 2, 1980 (United States) | F3: 5.8 | G3: 65000 | H3: Randal Kleiser | I3: Henry De Vere Stacpoole | J3: Brooke Shields | K3: United States | L3: 4500000 | M3: 58853106 | N3: Columbia Pictures | O3: 104 | P3: {=_xlfn.XLOOKUP(D3, CPI!$A:A, CPI!$B:B)} -> 82.4 | Q3: =IF(M3="","",PRODUCT(M3,CPI!$B$112/P3)) -> 2.1762793e+08
A4: Star Wars: Episode V - The Empire Strikes Back | B4: PG | C4: Action | D4: 1980 | E4: June 20, 1980 (United States) | F4: 8.7 | G4: 1200000 | H4: Irvin Kershner | I4: Leigh Brackett | J4: Mark Hamill | K4: United States | L4: 18000000 | M4: 538375067 | N4: Lucasfilm | O4: 124 | P4: {=_xlfn.XLOOKUP(D4, CPI!$A:A, CPI!$B:B)} -> 82.4 | Q4: =IF(M4="","",PRODUCT(M4,CPI!$B$112/P4)) -> 1.9908117e+09
A5: Airplane! | B5: PG | C5: Comedy | D5: 1980 | E5: July 2, 1980 (United States) | F5: 7.7 | G5: 221000 | H5: Jim Abrahams | I5: Jim Abrahams | J5: Robert Hays | K5: United States | L5: 3500000 | M5: 83453539 | N5: Paramount Pictures | O5: 88 | P5: {=_xlfn.XLOOKUP(D5, CPI!$A:A, CPI!$B:B)} -> 82.4 | Q5: =IF(M5="","",PRODUCT(M5,CPI!$B$112/P5)) -> 3.0859579e+08
A6: Caddyshack | B6: R | C6: Comedy | D6: 1980 | E6: July 25, 1980 (United States) | F6: 7.3 | G6: 108000 | H6: Harold Ramis | I6: Brian Doyle-Murray | J6: Chevy Chase | K6: United States | L6: 6000000 | M6: 39846344 | N6: Orion Pictures | O6: 98 | P6: {=_xlfn.XLOOKUP(D6, CPI!$A:A, CPI!$B:B)} -> 82.4 | Q6: =IF(M6="","",PRODUCT(M6,CPI!$B$112/P6)) -> 1.4734443e+08
A7: Friday the 13th | B7: R | C7: Horror | D7: 1980 | E7: May 9, 1980 (United States) | F7: 6.4 | G7: 123000 | H7: Sean S. Cunningham | I7: Victor Miller | J7: Betsy Palmer | K7: United States | L7: 550000 | M7: 39754601 | N7: Paramount Pictures | O7: 95 | P7: {=_xlfn.XLOOKUP(D7, CPI!$A:A, CPI!$B:B)} -> 82.4 | Q7: =IF(M7="","",PRODUCT(M7,CPI!$B$112/P7)) -> 1.4700518e+08
A8: The Blues Brothers | B8: R | C8: Action | D8: 1980 | E8: June 20, 1980 (United States) | F8: 7.9 | G8: 188000 | H8: John Landis | I8: Dan Aykroyd | J8: John Belushi | K8: United States | L8: 27000000 | M8: 115229890 | N8: Universal Pictures | O8: 133 | P8: {=_xlfn.XLOOKUP(D8, CPI!$A:A, CPI!$B:B)} -> 82.4 | Q8: =IF(M8="","",PRODUCT(M8,CPI!$B$112/P8)) -> 4.2609888e+08
A9: Raging Bull | B9: R | C9: Biography | D9: 1980 | E9: December 19, 1980 (United States) | F9: 8.2 | G9: 330000 | H9: Martin Scorsese | I9: Jake LaMotta | J9: Robert De Niro | K9: United States | L9: 18000000 | M9: 23402427 | N9: Chartoff-Winkler Productions | O9: 129 | P9: {=_xlfn.XLOOKUP(D9, CPI!$A:A, CPI!$B:B)} -> 82.4 | Q9: =IF(M9="","",PRODUCT(M9,CPI!$B$112/P9)) -> 86537858
A10: Superman II | B10: PG | C10: Action | D10: 1980 | E10: June 19, 1981 (United States) | F10: 6.8 | G10: 101000 | H10: Richard Lester | I10: Jerry Siegel | J10: Gene Hackman | K10: United States | L10: 54000000 | M10: 108185706 | N10: Dovemead Films | O10: 127 | P10: {=_xlfn.XLOOKUP(D10, CPI!$A:A, CPI!$B:B)} -> 82.4 | Q10: =IF(M10="","",PRODUCT(M10,CPI!$B$112/P10)) -> 4.0005078e+08
A11: The Long Riders | B11: R | C11: Biography | D11: 1980 | E11: May 16, 1980 (United States) | F11: 7 | G11: 10000 | H11: Walter Hill | I11: Bill Bryden | J11: David Carradine | K11: United States | L11: 10000000 | M11: 15795189 | N11: United Artists | O11: 100 | P11: {=_xlfn.XLOOKUP(D11, CPI!$A:A, CPI!$B:B)} -> 82.4 | Q11: =IF(M11="","",PRODUCT(M11,CPI!$B$112/P11)) -> 58407695
A12: Any Which Way You Can | B12: PG | C12: Action | D12: 1980 | E12: December 17, 1980 (United States) | F12: 6.1 | G12: 18000 | H12: Buddy Van Horn | I12: Stanford Sherman | J12: Clint Eastwood | K12: United States | L12: 15000000 | M12: 70687344 | N12: The Malpaso Company | O12: 116 | P12: {=_xlfn.XLOOKUP(D12, CPI!$A:A, CPI!$B:B)} -> 82.4 | Q12: =IF(M12="","",PRODUCT(M12,CPI!$B$112/P12)) -> 2.6138876e+08
A13: The Gods Must Be Crazy | B13: PG | C13: Adventure | D13: 1980 | E13: October 26, 1984 (United States) | F13: 7.3 | G13: 54000 | H13: Jamie Uys | I13: Jamie Uys | J13: N!xau | K13: South Africa | L13: 5000000 | M13: 30031783 | N13: C.A.T. Films | O13: 109 | P13: {=_xlfn.XLOOKUP(D13, CPI!$A:A, CPI!$B:B)} -> 82.4 | Q13: =IF(M13="","",PRODUCT(M13,CPI!$B$112/P13)) -> 1.1105199e+08
... A17: Somewhere in Time | B17: PG | C17: Drama | D17: 1980 | E17: October 3, 1980 (United States) | F17: 7.2 | G17: 27000 | H17: Jeannot Szwarc | I17: Richard Matheson | J17: Christopher Reeve | K17: United States | L17: 5100000 | M17: 9709597 | N17: Rastar Pictures | O17: 103 | P17: {=_xlfn.XLOOKUP(D17, CPI!$A:A, CPI!$B:B)} -> 82.4 | Q17: =IF(M17="","",PRODUCT(M17,CPI!$B$112/P17)) -> 35904299
A18: Fame | B18: R | C18: Drama | D18: 1980 | E18: May 16, 1980 (United States) | F18: 6.6 | G18: 21000 | H18: Alan Parker | I18: Christopher Gore | J18: Eddie Barth | K18: United States | M18: 21202829 | N18: Metro-Goldwyn-Mayer (MGM) | O18: 134 | P18: {=_xlfn.XLOOKUP(D18, CPI!$A:A, CPI!$B:B)} -> 82.4 | Q18: =IF(M18="","",PRODUCT(M18,CPI!$B$112/P18)) -> 78404150
A19: 9 to 5 | B19: PG | C19: Comedy | D19: 1980 | E19: December 19, 1980 (United States) | F19: 6.9 | G19: 29000 | H19: Colin Higgins | I19: Patricia Resnick | J19: Jane Fonda | K19: United States | L19: 10000000 | M19: 103300686 | N19: IPC Films | O19: 109 | P19: {=_xlfn.XLOOKUP(D19, CPI!$A:A, CPI!$B:B)} -> 82.4 | Q19: =IF(M19="","",PRODUCT(M19,CPI!$B$112/P19)) -> 3.8198688e+08
A20: The Fog | B20: R | C20: Horror | D20: 1980 | E20: February 8, 1980 (United States) | F20: 6.8 | G20: 66000 | H20: John Carpenter | I20: John Carpenter | J20: Adrienne Barbeau | K20: United States | L20: 1000000 | M20: 21448782 | N20: AVCO Embassy Pictures | O20: 89 | P20: {=_xlfn.XLOOKUP(D20, CPI!$A:A, CPI!$B:B)} -> 82.4 | Q20: =IF(M20="","",PRODUCT(M20,CPI!$B$112/P20)) -> 79313639
A21: Stir Crazy | B21: R | C21: Comedy | D21: 1980 | E21: December 12, 1980 (United States) | F21: 6.8 | G21: 26000 | H21: Sidney Poitier | I21: Bruce Jay Friedman | J21: Gene Wilder | K21: United States | M21: 101300000 | N21: Columbia Pictures | O21: 111 | P21: {=_xlfn.XLOOKUP(D21, CPI!$A:A, CPI!$B:B)} -> 82.4 | Q21: =IF(M21="","",PRODUCT(M21,CPI!$B$112/P21)) -> 3.7458871e+08
A22: Cruising | B22: R | C22: Crime | D22: 1980 | E22: February 15, 1980 (United States) | F22: 6.5 | G22: 20000 | H22: William Friedkin | I22: William Friedkin | J22: Al Pacino | K22: West Germany | L22: 11000000 | M22: 19814523 | N22: Lorimar Film Entertainment | O22: 102 | P22: {=_xlfn.XLOOKUP(D22, CPI!$A:A, CPI!$B:B)} -> 82.4 | Q22: =IF(M22="","",PRODUCT(M22,CPI!$B$112/P22)) -> 73270451
A23: Heaven's Gate | B23: R | C23: Adventure | D23: 1980 | E23: April 24, 1981 (United States) | F23: 6.8 | G23: 14000 | H23: Michael Cimino | I23: Michael Cimino | J23: Kris Kristofferson | K23: United States | L23: 44000000 | M23: 3484523 | N23: Partisan Productions | O23: 219 | P23: {=_xlfn.XLOOKUP(D23, CPI!$A:A, CPI!$B:B)} -> 82.4 | Q23: =IF(M23="","",PRODUCT(M23,CPI!$B$112/P23)) -> 12885123
A24: The Final Countdown | B24: PG | C24: Action | D24: 1980 | E24: August 1, 1980 (United States) | F24: 6.7 | G24: 22000 | H24: Don Taylor | I24: Thomas Hunter | J24: Kirk Douglas | K24: United States | L24: 12000000 | M24: 16647800 | N24: Bryna Productions | O24: 103 | P24: {=_xlfn.XLOOKUP(D24, CPI!$A:A, CPI!$B:B)} -> 82.4 | Q24: =IF(M24="","",PRODUCT(M24,CPI!$B$112/P24)) -> 61560493
A25: Xanadu | B25: PG | C25: Fantasy | D25: 1980 | E25: August 8, 1980 (United States) | F25: 5.3 | G25: 12000 | H25: Robert Greenwald | I25: Richard Christian Danus | J25: Olivia Newton-John | K25: United States | L25: 20000000 | M25: 22762571 | N25: Universal Pictures | O25: 96 | P25: {=_xlfn.XLOOKUP(D25, CPI!$A:A, CPI!$B:B)} -> 82.4 | Q25: =IF(M25="","",PRODUCT(M25,CPI!$B$112/P25)) -> 84171789
A26: Urban Cowboy | B26: PG | C26: Drama | D26: 1980 | E26: June 6, 1980 (United States) | F26: 6.4 | G26: 14000 | H26: James Bridges | I26: Aaron Latham | J26: John Travolta | K26: United States | M26: 46918287 | N26: Paramount Pictures | O26: 132 | P26: {=_xlfn.XLOOKUP(D26, CPI!$A:A, CPI!$B:B)} -> 82.4 | Q26: =IF(M26="","",PRODUCT(M26,CPI!$B$112/P26)) -> 1.7349517e+08
A27: Altered States | B27: R | C27: Horror | D27: 1980 | E27: December 25, 1980 (United States) | F27: 6.9 | G27: 33000 | H27: Ken Russell | I27: Paddy Chayefsky | J27: William Hurt | K27: United States | M27: 19853892 | N27: Warner Bros. | O27: 102 | P27: {=_xlfn.XLOOKUP(D27, CPI!$A:A, CPI!$B:B)} -> 82.4 | Q27: =IF(M27="","",PRODUCT(M27,CPI!$B$112/P27)) -> 73416030
A28: Little Darlings | B28: R | C28: Comedy | D28: 1980 | E28: March 21, 1980 (United States) | F28: 6.5 | G28: 5100 | H28: Ron Maxwell | I28: Kimi Peck | J28: Tatum O'Neal | K28: United States | M28: 34326249 | N28: Stephen Friedman/Kings Road Productions | O28: 96 | P28: {=_xlfn.XLOOKUP(D28, CPI!$A:A, CPI!$B:B)} -> 82.4 | Q28: =IF(M28="","",PRODUCT(M28,CPI!$B$112/P28)) -> 1.2693214e+08
A29: Raise the Titanic | B29: PG | C29: Action | D29: 1980 | E29: August 1, 1980 (United States) | F29: 5 | G29: 4100 | H29: Jerry Jameson | I29: Adam Kennedy | J29: Jason Robards | K29: United Kingdom | L29: 36000000 | N29: ITC Films | O29: 115 | P29: {=_xlfn.XLOOKUP(D29, CPI!$A:A, CPI!$B:B)} -> 82.4 | Q29: =IF(M29="","",PRODUCT(M29,CPI!$B$112/P29))
A30: Brubaker | B30: R | C30: Crime | D30: 1980 | E30: June 20, 1980 (United States) | F30: 7.2 | G30: 17000 | H30: Stuart Rosenberg | I30: W.D. Richter | J30: Robert Redford | K30: United States | L30: 9000000 | M30: 37121708 | N30: Twentieth Century Fox | O30: 131 | P30: {=_xlfn.XLOOKUP(D30, CPI!$A:A, CPI!$B:B)} -> 82.4 | Q30: =IF(M30="","",PRODUCT(M30,CPI!$B$112/P30)) -> 1.3726923e+08
A31: American Gigolo | B31: R | C31: Crime | D31: 1980 | E31: February 1, 1980 (United States) | F31: 6.2 | G31: 22000 | H31: Paul Schrader | I31: Paul Schrader | J31: Richard Gere | K31: United States | L31: 4800000 | M31: 22743674 | N31: Paramount Pictures | O31: 117 | P31: {=_xlfn.XLOOKUP(D31, CPI!$A:A, CPI!$B:B)} -> 82.4 | Q31: =IF(M31="","",PRODUCT(M31,CPI!$B$112/P31)) -> 84101911
A32: My Bodyguard | B32: PG | C32: Comedy | D32: 1980 | E32: September 26, 1980 (United States) | F32: 7.1 | G32: 8900 | H32: Tony Bill | I32: Alan Ormsby | J32: Chris Makepeace | K32: United States | M32: 22482952 | N32: Twentieth Century Fox | O32: 102 | P32: {=_xlfn.XLOOKUP(D32, CPI!$A:A, CPI!$B:B)} -> 82.4 | Q32: =IF(M32="","",PRODUCT(M32,CPI!$B$112/P32)) -> 83137809
A33: Prom Night | B33: R | C33: Horror | D33: 1980 | E33: July 18, 1980 (United States) | F33: 5.4 | G33: 16000 | H33: Paul Lynch | I33: William Gray | J33: Leslie Nielsen | K33: Canada | M33: 14796236 | N33: Guardian Trust Company | O33: 92 | P33: {=_xlfn.XLOOKUP(D33, CPI!$A:A, CPI!$B:B)} -> 82.4 | Q33: =IF(M33="","",PRODUCT(M33,CPI!$B$112/P33)) -> 54713751
A34: Smokey and the Bandit II | B34: PG | C34: Action | D34: 1980 | E34: August 15, 1980 (United States) | F34: 5.3 | G34: 15000 | H34: Hal Needham | I34: Hal Needham | J34: Burt Reynolds | K34: United States | M34: 66132626 | N34: Universal Pictures | O34: 100 | P34: {=_xlfn.XLOOKUP(D34, CPI!$A:A, CPI!$B:B)} -> 82.4 | Q34: =IF(M34="","",PRODUCT(M34,CPI!$B$112/P34)) -> 2.4454625e+08
A35: Cattle Annie and Little Britches | B35: PG | C35: Drama | D35: 1980 | E35: April 24, 1981 (United States) | F35: 6.1 | G35: 604 | H35: Lamont Johnson | I35: David Eyre | J35: Scott Glenn | K35: United States | L35: 5100000 | M35: 534816 | N35: Cattle Annie Productions | O35: 97 | P35: {=_xlfn.XLOOKUP(D35, CPI!$A:A, CPI!$B:B)} -> 82.4 | Q35: =IF(M35="","",PRODUCT(M35,CPI!$B$112/P35)) -> 1977650.9
A36: Seems Like Old Times | B36: PG | C36: Comedy | D36: 1980 | E36: December 19, 1980 (United States) | F36: 6.7 | G36: 9100 | H36: Jay Sandrich | I36: Neil Simon | J36: Goldie Hawn | K36: United States | M36: 43995918 | N36: Rastar Films | O36: 102 | P36: {=_xlfn.XLOOKUP(D36, CPI!$A:A, CPI!$B:B)} -> 82.4 | Q36: =IF(M36="","",PRODUCT(M36,CPI!$B$112/P36)) -> 1.6268879e+08
A37: Private Benjamin | B37: R | C37: Comedy | D37: 1980 | E37: October 10, 1980 (United States) | F37: 6.2 | G37: 24000 | H37: Howard Zieff | I37: Nancy Meyers | J37: Goldie Hawn | K37: United States | L37: 10000000 | M37: 69847348 | N37: Warner Bros. | O37: 109 | P37: {=_xlfn.XLOOKUP(D37, CPI!$A:A, CPI!$B:B)} -> 82.4 | Q37: =IF(M37="","",PRODUCT(M37,CPI!$B$112/P37)) -> 2.5828261e+08
A38: The Hollywood Knights | B38: R | C38: Comedy | D38: 1980 | E38: May 30, 1980 (United States) | F38: 6.3 | G38: 4300 | H38: Floyd Mutrux | I38: Floyd Mutrux | J38: Tony Danza | K38: United States | L38: 4000000 | M38: 10000000 | N38: PolyGram Filmed Entertainment | O38: 91 | P38: {=_xlfn.XLOOKUP(D38, CPI!$A:A, CPI!$B:B)} -> 82.4 | Q38: =IF(M38="","",PRODUCT(M38,CPI!$B$112/P38)) -> 36978155
A39: Motel Hell | B39: R | C39: Comedy | D39: 1980 | E39: October 24, 1980 (United States) | F39: 6 | G39: 11000 | H39: Kevin Connor | I39: Robert Jaffe | J39: Rory Calhoun | K39: United States | L39: 3000000 | M39: 6342668 | N39: Camp Hill | O39: 101 | P39: {=_xlfn.XLOOKUP(D39, CPI!$A:A, CPI!$B:B)} -> 82.4 | Q39: =IF(M39="","",PRODUCT(M39,CPI!$B$112/P39)) -> 23454016
A40: The Jazz Singer | B40: PG | C40: Drama | D40: 1980 | E40: December 19, 1980 (United States) | F40: 5.9 | G40: 4000 | H40: Richard Fleischer | I40: Samson Raphaelson | J40: Laurence Olivier | K40: United States | M40: 27118000 | N40: EMI Films | O40: 115 | P40: {=_xlfn.XLOOKUP(D40, CPI!$A:A, CPI!$B:B)} -> 82.4 | Q40: =IF(M40="","",PRODUCT(M40,CPI!$B$112/P40)) -> 1.0027736e+08
A41: Coal Miner's Daughter | B41: PG | C41: Biography | D41: 1980 | E41: March 7, 1980 (United States) | F41: 7.5 | G41: 17000 | H41: Michael Apted | I41: Thomas Rickman | J41: Sissy Spacek | K41: United States | M41: 67182787 | N41: Universal Pictures | O41: 124 | P41: {=_xlfn.XLOOKUP(D41, CPI!$A:A, CPI!$B:B)} -> 82.4 | Q41: =IF(M41="","",PRODUCT(M41,CPI!$B$112/P41)) -> 2.4842955e+08
A42: The Watcher in the Woods | B42: PG | C42: Family | D42: 1980 | E42: October 9, 1981 (United States) | F42: 6.3 | G42: 5700 | H42: John Hough | I42: Brian Clemens | J42: Bette Davis | K42: United States | M42: 5000000 | N42: Walt Disney Productions | O42: 84 | P42: {=_xlfn.XLOOKUP(D42, CPI!$A:A, CPI!$B:B)} -> 82.4 | Q42: =IF(M42="","",PRODUCT(M42,CPI!$B$112/P42)) -> 18489078
A43: Breaker Morant | B43: PG | C43: Drama | D43: 1980 | E43: July 3, 1980 (Australia) | F43: 7.9 | G43: 13000 | H43: Bruce Beresford | I43: Jonathan Hardy | J43: Edward Woodward | K43: Australia | N43: The South Australian Film Corporation | O43: 107 | P43: {=_xlfn.XLOOKUP(D43, CPI!$A:A, CPI!$B:B)} -> 82.4 | Q43: =IF(M43="","",PRODUCT(M43,CPI!$B$112/P43))
...
